2022-04-09 12:00:01,281 INFO    MainThread:24008 [internal.py:wandb_internal():92] W&B internal server running at pid: 24008, started at: 2022-04-09 12:00:01.281496
2022-04-09 12:00:01,284 INFO    WriterThread:24008 [datastore.py:open_for_write():77] open: C:\Users\orteg\Dropbox\BGGN-main\wandb\offline-run-20220409_120000-2snr2hj1\run-2snr2hj1.wandb
2022-04-09 12:00:01,285 DEBUG   HandlerThread:24008 [handler.py:handle_request():141] handle_request: run_start
2022-04-09 12:00:01,304 DEBUG   HandlerThread:24008 [meta.py:__init__():37] meta init
2022-04-09 12:00:01,304 DEBUG   HandlerThread:24008 [meta.py:__init__():51] meta init done
2022-04-09 12:00:01,305 DEBUG   HandlerThread:24008 [meta.py:probe():211] probe
2022-04-09 12:00:01,384 DEBUG   HandlerThread:24008 [git.py:repo():33] git repository is invalid
2022-04-09 12:00:01,384 DEBUG   HandlerThread:24008 [meta.py:_save_pip():55] save pip
2022-04-09 12:00:01,384 DEBUG   HandlerThread:24008 [meta.py:_save_pip():69] save pip done
2022-04-09 12:00:01,385 DEBUG   HandlerThread:24008 [meta.py:_save_conda():76] save conda
2022-04-09 12:00:01,392 ERROR   HandlerThread:24008 [meta.py:_save_conda():85] Error saving conda packages
Traceback (most recent call last):
  File "C:\Users\orteg\Anaconda3\envs\bggn_env\lib\site-packages\wandb\sdk\internal\meta.py", line 81, in _save_conda
    subprocess.call(
  File "C:\Users\orteg\Anaconda3\envs\bggn_env\lib\subprocess.py", line 349, in call
    with Popen(*popenargs, **kwargs) as p:
  File "C:\Users\orteg\Anaconda3\envs\bggn_env\lib\subprocess.py", line 951, in __init__
    self._execute_child(args, executable, preexec_fn, close_fds,
  File "C:\Users\orteg\Anaconda3\envs\bggn_env\lib\subprocess.py", line 1420, in _execute_child
    hp, ht, pid, tid = _winapi.CreateProcess(executable, args,
FileNotFoundError: [WinError 2] The system cannot find the file specified
2022-04-09 12:00:01,394 DEBUG   HandlerThread:24008 [meta.py:_save_conda():86] save conda done
2022-04-09 12:00:01,394 DEBUG   HandlerThread:24008 [meta.py:probe():249] probe done
2022-04-09 12:01:26,746 WARNING MainThread:24008 [internal.py:wandb_internal():155] Internal process interrupt: 1
2022-04-09 12:02:03,377 WARNING MainThread:24008 [internal.py:is_dead():387] Internal process exiting, parent pid 11256 disappeared
2022-04-09 12:02:03,377 ERROR   MainThread:24008 [internal.py:wandb_internal():151] Internal process shutdown.
2022-04-09 12:02:03,893 INFO    SenderThread:24008 [sender.py:finish():1078] shutting down sender
2022-04-09 12:02:04,051 INFO    WriterThread:24008 [datastore.py:close():281] close: C:\Users\orteg\Dropbox\BGGN-main\wandb\offline-run-20220409_120000-2snr2hj1\run-2snr2hj1.wandb
2022-04-09 12:02:04,051 INFO    HandlerThread:24008 [handler.py:finish():778] shutting down handler
2022-04-09 12:02:04,052 INFO    MainThread:24008 [internal.py:handle_exit():82] Internal process exited
