2022-04-09 12:02:06,055 INFO    MainThread:26156 [internal.py:wandb_internal():92] W&B internal server running at pid: 26156, started at: 2022-04-09 12:02:06.054137
2022-04-09 12:02:06,057 INFO    WriterThread:26156 [datastore.py:open_for_write():77] open: C:\Users\orteg\Dropbox\BGGN-main\wandb\offline-run-20220409_120204-rgqujwds\run-rgqujwds.wandb
2022-04-09 12:02:06,059 DEBUG   HandlerThread:26156 [handler.py:handle_request():141] handle_request: run_start
2022-04-09 12:02:06,076 DEBUG   HandlerThread:26156 [meta.py:__init__():37] meta init
2022-04-09 12:02:06,076 DEBUG   HandlerThread:26156 [meta.py:__init__():51] meta init done
2022-04-09 12:02:06,077 DEBUG   HandlerThread:26156 [meta.py:probe():211] probe
2022-04-09 12:02:06,147 DEBUG   HandlerThread:26156 [git.py:repo():33] git repository is invalid
2022-04-09 12:02:06,147 DEBUG   HandlerThread:26156 [meta.py:_save_pip():55] save pip
2022-04-09 12:02:06,148 DEBUG   HandlerThread:26156 [meta.py:_save_pip():69] save pip done
2022-04-09 12:02:06,148 DEBUG   HandlerThread:26156 [meta.py:_save_conda():76] save conda
2022-04-09 12:02:06,154 ERROR   HandlerThread:26156 [meta.py:_save_conda():85] Error saving conda packages
Traceback (most recent call last):
  File "C:\Users\orteg\Anaconda3\envs\bggn_env\lib\site-packages\wandb\sdk\internal\meta.py", line 81, in _save_conda
    subprocess.call(
  File "C:\Users\orteg\Anaconda3\envs\bggn_env\lib\subprocess.py", line 349, in call
    with Popen(*popenargs, **kwargs) as p:
  File "C:\Users\orteg\Anaconda3\envs\bggn_env\lib\subprocess.py", line 951, in __init__
    self._execute_child(args, executable, preexec_fn, close_fds,
  File "C:\Users\orteg\Anaconda3\envs\bggn_env\lib\subprocess.py", line 1420, in _execute_child
    hp, ht, pid, tid = _winapi.CreateProcess(executable, args,
FileNotFoundError: [WinError 2] The system cannot find the file specified
2022-04-09 12:02:06,155 DEBUG   HandlerThread:26156 [meta.py:_save_conda():86] save conda done
2022-04-09 12:02:06,155 DEBUG   HandlerThread:26156 [meta.py:probe():249] probe done
2022-04-09 12:03:47,049 WARNING MainThread:26156 [internal.py:wandb_internal():155] Internal process interrupt: 1
2022-04-09 12:03:48,756 WARNING MainThread:26156 [internal.py:wandb_internal():155] Internal process interrupt: 2
2022-04-09 12:03:48,763 ERROR   MainThread:26156 [internal.py:wandb_internal():158] Internal process interrupted.
2022-04-09 12:03:48,766 INFO    HandlerThread:26156 [handler.py:finish():778] shutting down handler
2022-04-09 12:03:48,766 INFO    WriterThread:26156 [datastore.py:close():281] close: C:\Users\orteg\Dropbox\BGGN-main\wandb\offline-run-20220409_120204-rgqujwds\run-rgqujwds.wandb
2022-04-09 12:03:49,048 INFO    SenderThread:26156 [sender.py:finish():1078] shutting down sender
2022-04-09 12:03:49,049 INFO    MainThread:26156 [internal.py:handle_exit():82] Internal process exited
