2022-04-06 15:50:24,284 INFO    MainThread:29656 [internal.py:wandb_internal():92] W&B internal server running at pid: 29656, started at: 2022-04-06 15:50:24.284122
2022-04-06 15:50:24,287 INFO    WriterThread:29656 [datastore.py:open_for_write():77] open: C:\Users\orteg\Dropbox\BGGN-main\wandb\offline-run-20220406_155023-4p3w4bmc\run-4p3w4bmc.wandb
2022-04-06 15:50:24,288 DEBUG   HandlerThread:29656 [handler.py:handle_request():141] handle_request: run_start
2022-04-06 15:50:24,308 DEBUG   HandlerThread:29656 [meta.py:__init__():37] meta init
2022-04-06 15:50:24,308 DEBUG   HandlerThread:29656 [meta.py:__init__():51] meta init done
2022-04-06 15:50:24,308 DEBUG   HandlerThread:29656 [meta.py:probe():211] probe
2022-04-06 15:50:24,374 DEBUG   HandlerThread:29656 [git.py:repo():33] git repository is invalid
2022-04-06 15:50:24,374 DEBUG   HandlerThread:29656 [meta.py:_save_pip():55] save pip
2022-04-06 15:50:24,375 DEBUG   HandlerThread:29656 [meta.py:_save_pip():69] save pip done
2022-04-06 15:50:24,375 DEBUG   HandlerThread:29656 [meta.py:_save_conda():76] save conda
2022-04-06 15:50:24,381 ERROR   HandlerThread:29656 [meta.py:_save_conda():85] Error saving conda packages
Traceback (most recent call last):
  File "C:\Users\orteg\Anaconda3\envs\bggn_env\lib\site-packages\wandb\sdk\internal\meta.py", line 81, in _save_conda
    subprocess.call(
  File "C:\Users\orteg\Anaconda3\envs\bggn_env\lib\subprocess.py", line 349, in call
    with Popen(*popenargs, **kwargs) as p:
  File "C:\Users\orteg\Anaconda3\envs\bggn_env\lib\subprocess.py", line 951, in __init__
    self._execute_child(args, executable, preexec_fn, close_fds,
  File "C:\Users\orteg\Anaconda3\envs\bggn_env\lib\subprocess.py", line 1420, in _execute_child
    hp, ht, pid, tid = _winapi.CreateProcess(executable, args,
FileNotFoundError: [WinError 2] The system cannot find the file specified
2022-04-06 15:50:24,383 DEBUG   HandlerThread:29656 [meta.py:_save_conda():86] save conda done
2022-04-06 15:50:24,383 DEBUG   HandlerThread:29656 [meta.py:probe():249] probe done
2022-04-06 15:51:12,677 WARNING MainThread:29656 [internal.py:wandb_internal():155] Internal process interrupt: 1
2022-04-06 15:51:13,439 WARNING MainThread:29656 [internal.py:wandb_internal():155] Internal process interrupt: 2
2022-04-06 15:51:13,439 ERROR   MainThread:29656 [internal.py:wandb_internal():158] Internal process interrupted.
2022-04-06 15:51:13,661 INFO    SenderThread:29656 [sender.py:finish():1078] shutting down sender
2022-04-06 15:51:14,083 INFO    WriterThread:29656 [datastore.py:close():281] close: C:\Users\orteg\Dropbox\BGGN-main\wandb\offline-run-20220406_155023-4p3w4bmc\run-4p3w4bmc.wandb
2022-04-06 15:51:14,083 INFO    HandlerThread:29656 [handler.py:finish():778] shutting down handler
2022-04-06 15:51:14,084 INFO    MainThread:29656 [internal.py:handle_exit():82] Internal process exited
