2022-04-06 15:52:16,479 INFO    MainThread:27980 [internal.py:wandb_internal():92] W&B internal server running at pid: 27980, started at: 2022-04-06 15:52:16.479111
2022-04-06 15:52:16,482 INFO    WriterThread:27980 [datastore.py:open_for_write():77] open: C:\Users\orteg\Dropbox\BGGN-main\wandb\offline-run-20220406_155215-2g46q4wh\run-2g46q4wh.wandb
2022-04-06 15:52:16,483 DEBUG   HandlerThread:27980 [handler.py:handle_request():141] handle_request: run_start
2022-04-06 15:52:16,502 DEBUG   HandlerThread:27980 [meta.py:__init__():37] meta init
2022-04-06 15:52:16,502 DEBUG   HandlerThread:27980 [meta.py:__init__():51] meta init done
2022-04-06 15:52:16,502 DEBUG   HandlerThread:27980 [meta.py:probe():211] probe
2022-04-06 15:52:16,577 DEBUG   HandlerThread:27980 [git.py:repo():33] git repository is invalid
2022-04-06 15:52:16,578 DEBUG   HandlerThread:27980 [meta.py:_save_pip():55] save pip
2022-04-06 15:52:16,578 DEBUG   HandlerThread:27980 [meta.py:_save_pip():69] save pip done
2022-04-06 15:52:16,579 DEBUG   HandlerThread:27980 [meta.py:_save_conda():76] save conda
2022-04-06 15:52:16,585 ERROR   HandlerThread:27980 [meta.py:_save_conda():85] Error saving conda packages
Traceback (most recent call last):
  File "C:\Users\orteg\Anaconda3\envs\bggn_env\lib\site-packages\wandb\sdk\internal\meta.py", line 81, in _save_conda
    subprocess.call(
  File "C:\Users\orteg\Anaconda3\envs\bggn_env\lib\subprocess.py", line 349, in call
    with Popen(*popenargs, **kwargs) as p:
  File "C:\Users\orteg\Anaconda3\envs\bggn_env\lib\subprocess.py", line 951, in __init__
    self._execute_child(args, executable, preexec_fn, close_fds,
  File "C:\Users\orteg\Anaconda3\envs\bggn_env\lib\subprocess.py", line 1420, in _execute_child
    hp, ht, pid, tid = _winapi.CreateProcess(executable, args,
FileNotFoundError: [WinError 2] The system cannot find the file specified
2022-04-06 15:52:16,586 DEBUG   HandlerThread:27980 [meta.py:_save_conda():86] save conda done
2022-04-06 15:52:16,586 DEBUG   HandlerThread:27980 [meta.py:probe():249] probe done
2022-04-06 15:58:51,436 WARNING MainThread:27980 [internal.py:wandb_internal():155] Internal process interrupt: 1
2022-04-06 15:59:01,915 WARNING MainThread:27980 [internal.py:is_dead():387] Internal process exiting, parent pid 3336 disappeared
2022-04-06 15:59:01,916 ERROR   MainThread:27980 [internal.py:wandb_internal():151] Internal process shutdown.
2022-04-06 15:59:02,345 INFO    HandlerThread:27980 [handler.py:finish():778] shutting down handler
2022-04-06 15:59:02,347 INFO    WriterThread:27980 [datastore.py:close():281] close: C:\Users\orteg\Dropbox\BGGN-main\wandb\offline-run-20220406_155215-2g46q4wh\run-2g46q4wh.wandb
2022-04-06 15:59:02,628 INFO    SenderThread:27980 [sender.py:finish():1078] shutting down sender
2022-04-06 15:59:02,640 INFO    MainThread:27980 [internal.py:handle_exit():82] Internal process exited
