[2022-04-06 14:03:00] INFO (exp_logger/MainThread) No Edges vs. Edges in training set = 1.0301220865239213
BEFORE EPOCH ! !! ! !
[2022-04-06 14:11:15] ERROR (exp_logger/MainThread) Traceback (most recent call last):
  File "C:\Users\orteg\Dropbox\BGGN-main\run_exp.py", line 59, in main
    runner.train()
  File "C:\Users\orteg\Dropbox\BGGN-main\runner\bggn_runner.py", line 285, in train
    train_loss = model(*batch_fwd).mean()
  File "C:\Users\orteg\Anaconda3\envs\bggn_env\lib\site-packages\torch\nn\modules\module.py", line 1051, in _call_impl
    return forward_call(*input, **kwargs)
  File "C:\Users\orteg\Dropbox\BGGN-main\utils\data_parallel.py", line 104, in forward
    return self.module(*inputs[0], **kwargs[0])
  File "C:\Users\orteg\Anaconda3\envs\bggn_env\lib\site-packages\torch\nn\modules\module.py", line 1051, in _call_impl
    return forward_call(*input, **kwargs)
  File "C:\Users\orteg\Dropbox\BGGN-main\model\bggn_model.py", line 577, in forward
    log_theta, log_alpha, bpr_loss = self._inference(
  File "C:\Users\orteg\Dropbox\BGGN-main\model\bggn_model.py", line 237, in _inference
    user_embedding = self.users_feature[user_idx]
RuntimeError: CUDA error: device-side assert triggered
INFO  | 2022-04-06 14:03:00,013 | bggn_runner.py            | line 157  : No Edges vs. Edges in training set = 1.0301220865239213
ERROR | 2022-04-06 14:11:15,119 | run_exp.py                | line 64   : Traceback (most recent call last):
  File "C:\Users\orteg\Dropbox\BGGN-main\run_exp.py", line 59, in main
    runner.train()
  File "C:\Users\orteg\Dropbox\BGGN-main\runner\bggn_runner.py", line 285, in train
    train_loss = model(*batch_fwd).mean()
  File "C:\Users\orteg\Anaconda3\envs\bggn_env\lib\site-packages\torch\nn\modules\module.py", line 1051, in _call_impl
    return forward_call(*input, **kwargs)
  File "C:\Users\orteg\Dropbox\BGGN-main\utils\data_parallel.py", line 104, in forward
    return self.module(*inputs[0], **kwargs[0])
  File "C:\Users\orteg\Anaconda3\envs\bggn_env\lib\site-packages\torch\nn\modules\module.py", line 1051, in _call_impl
    return forward_call(*input, **kwargs)
  File "C:\Users\orteg\Dropbox\BGGN-main\model\bggn_model.py", line 577, in forward
    log_theta, log_alpha, bpr_loss = self._inference(
  File "C:\Users\orteg\Dropbox\BGGN-main\model\bggn_model.py", line 237, in _inference
    user_embedding = self.users_feature[user_idx]
RuntimeError: CUDA error: device-side assert triggered