2022-04-06 13:37:34,404 INFO    MainThread:25964 [internal.py:wandb_internal():92] W&B internal server running at pid: 25964, started at: 2022-04-06 13:37:34.404324
2022-04-06 13:37:34,407 INFO    WriterThread:25964 [datastore.py:open_for_write():77] open: C:\Users\orteg\Dropbox\BGGN-main\wandb\offline-run-20220406_133733-1ir6jgxj\run-1ir6jgxj.wandb
2022-04-06 13:37:34,408 DEBUG   HandlerThread:25964 [handler.py:handle_request():141] handle_request: run_start
2022-04-06 13:37:34,428 DEBUG   HandlerThread:25964 [meta.py:__init__():37] meta init
2022-04-06 13:37:34,429 DEBUG   HandlerThread:25964 [meta.py:__init__():51] meta init done
2022-04-06 13:37:34,429 DEBUG   HandlerThread:25964 [meta.py:probe():211] probe
2022-04-06 13:37:34,513 DEBUG   HandlerThread:25964 [git.py:repo():33] git repository is invalid
2022-04-06 13:37:34,513 DEBUG   HandlerThread:25964 [meta.py:_save_pip():55] save pip
2022-04-06 13:37:34,513 DEBUG   HandlerThread:25964 [meta.py:_save_pip():69] save pip done
2022-04-06 13:37:34,514 DEBUG   HandlerThread:25964 [meta.py:_save_conda():76] save conda
2022-04-06 13:37:34,520 ERROR   HandlerThread:25964 [meta.py:_save_conda():85] Error saving conda packages
Traceback (most recent call last):
  File "C:\Users\orteg\Anaconda3\envs\bggn_env\lib\site-packages\wandb\sdk\internal\meta.py", line 81, in _save_conda
    subprocess.call(
  File "C:\Users\orteg\Anaconda3\envs\bggn_env\lib\subprocess.py", line 349, in call
    with Popen(*popenargs, **kwargs) as p:
  File "C:\Users\orteg\Anaconda3\envs\bggn_env\lib\subprocess.py", line 951, in __init__
    self._execute_child(args, executable, preexec_fn, close_fds,
  File "C:\Users\orteg\Anaconda3\envs\bggn_env\lib\subprocess.py", line 1420, in _execute_child
    hp, ht, pid, tid = _winapi.CreateProcess(executable, args,
FileNotFoundError: [WinError 2] The system cannot find the file specified
2022-04-06 13:37:34,522 DEBUG   HandlerThread:25964 [meta.py:_save_conda():86] save conda done
2022-04-06 13:37:34,522 DEBUG   HandlerThread:25964 [meta.py:probe():249] probe done
2022-04-06 13:43:46,036 DEBUG   HandlerThread:25964 [handler.py:handle_request():141] handle_request: partial_history
2022-04-06 13:46:11,727 WARNING MainThread:25964 [internal.py:wandb_internal():155] Internal process interrupt: 1
2022-04-06 13:46:29,456 WARNING MainThread:25964 [internal.py:is_dead():387] Internal process exiting, parent pid 18476 disappeared
2022-04-06 13:46:29,457 ERROR   MainThread:25964 [internal.py:wandb_internal():151] Internal process shutdown.
2022-04-06 13:46:30,097 INFO    WriterThread:25964 [datastore.py:close():281] close: C:\Users\orteg\Dropbox\BGGN-main\wandb\offline-run-20220406_133733-1ir6jgxj\run-1ir6jgxj.wandb
2022-04-06 13:46:30,098 INFO    HandlerThread:25964 [handler.py:finish():778] shutting down handler
2022-04-06 13:46:30,463 INFO    SenderThread:25964 [sender.py:finish():1078] shutting down sender
2022-04-06 13:46:30,469 INFO    MainThread:25964 [internal.py:handle_exit():82] Internal process exited
