2022-04-06 13:46:34,634 INFO    MainThread:14416 [internal.py:wandb_internal():92] W&B internal server running at pid: 14416, started at: 2022-04-06 13:46:34.633474
2022-04-06 13:46:34,636 INFO    WriterThread:14416 [datastore.py:open_for_write():77] open: C:\Users\orteg\Dropbox\BGGN-main\wandb\offline-run-20220406_134633-1s91uidk\run-1s91uidk.wandb
2022-04-06 13:46:34,637 DEBUG   HandlerThread:14416 [handler.py:handle_request():141] handle_request: run_start
2022-04-06 13:46:34,656 DEBUG   HandlerThread:14416 [meta.py:__init__():37] meta init
2022-04-06 13:46:34,656 DEBUG   HandlerThread:14416 [meta.py:__init__():51] meta init done
2022-04-06 13:46:34,657 DEBUG   HandlerThread:14416 [meta.py:probe():211] probe
2022-04-06 13:46:34,731 DEBUG   HandlerThread:14416 [git.py:repo():33] git repository is invalid
2022-04-06 13:46:34,732 DEBUG   HandlerThread:14416 [meta.py:_save_pip():55] save pip
2022-04-06 13:46:34,733 DEBUG   HandlerThread:14416 [meta.py:_save_pip():69] save pip done
2022-04-06 13:46:34,733 DEBUG   HandlerThread:14416 [meta.py:_save_conda():76] save conda
2022-04-06 13:46:34,740 ERROR   HandlerThread:14416 [meta.py:_save_conda():85] Error saving conda packages
Traceback (most recent call last):
  File "C:\Users\orteg\Anaconda3\envs\bggn_env\lib\site-packages\wandb\sdk\internal\meta.py", line 81, in _save_conda
    subprocess.call(
  File "C:\Users\orteg\Anaconda3\envs\bggn_env\lib\subprocess.py", line 349, in call
    with Popen(*popenargs, **kwargs) as p:
  File "C:\Users\orteg\Anaconda3\envs\bggn_env\lib\subprocess.py", line 951, in __init__
    self._execute_child(args, executable, preexec_fn, close_fds,
  File "C:\Users\orteg\Anaconda3\envs\bggn_env\lib\subprocess.py", line 1420, in _execute_child
    hp, ht, pid, tid = _winapi.CreateProcess(executable, args,
FileNotFoundError: [WinError 2] The system cannot find the file specified
2022-04-06 13:46:34,742 DEBUG   HandlerThread:14416 [meta.py:_save_conda():86] save conda done
2022-04-06 13:46:34,742 DEBUG   HandlerThread:14416 [meta.py:probe():249] probe done
2022-04-06 13:53:19,652 DEBUG   HandlerThread:14416 [handler.py:handle_request():141] handle_request: partial_history
2022-04-06 13:56:24,935 DEBUG   HandlerThread:14416 [handler.py:handle_request():141] handle_request: partial_history
2022-04-06 13:59:26,652 DEBUG   HandlerThread:14416 [handler.py:handle_request():141] handle_request: partial_history
2022-04-06 13:59:56,295 WARNING MainThread:14416 [internal.py:wandb_internal():155] Internal process interrupt: 1
2022-04-06 14:00:03,889 WARNING MainThread:14416 [internal.py:is_dead():387] Internal process exiting, parent pid 17968 disappeared
2022-04-06 14:00:03,889 ERROR   MainThread:14416 [internal.py:wandb_internal():151] Internal process shutdown.
2022-04-06 14:00:04,354 INFO    WriterThread:14416 [datastore.py:close():281] close: C:\Users\orteg\Dropbox\BGGN-main\wandb\offline-run-20220406_134633-1s91uidk\run-1s91uidk.wandb
2022-04-06 14:00:04,355 INFO    HandlerThread:14416 [handler.py:finish():778] shutting down handler
2022-04-06 14:00:04,883 INFO    SenderThread:14416 [sender.py:finish():1078] shutting down sender
2022-04-06 14:00:04,886 INFO    MainThread:14416 [internal.py:handle_exit():82] Internal process exited
